2025-10-17 09:35:07,355 - ERROR - Ocurrió un error inesperado al generar el PDF:
Cannot use PosixPath('/home/krisis/PROYECTOS/Cotizadores[]/pdfs/Cotizacion_Nro_1.pdf') as a filename or file
Traceback (most recent call last):
  File "/home/krisis/PROYECTOS/Cotizadores[]/main.py", line 658, in generar_pdf
    c.save()
    ~~~~~~^^
  File "/home/krisis/PROYECTOS/Copiloto_IA/venv/lib/python3.13/site-packages/reportlab/pdfgen/canvas.py", line 1301, in save
    self._doc.SaveToFile(self._filename, self)
    ~~~~~~~~~~~~~~~~~~~~^^^^^^^^^^^^^^^^^^^^^^
  File "/home/krisis/PROYECTOS/Copiloto_IA/venv/lib/python3.13/site-packages/reportlab/pdfbase/pdfdoc.py", line 210, in SaveToFile
    raise TypeError('Cannot use %s as a filename or file' % repr(filename))
TypeError: Cannot use PosixPath('/home/krisis/PROYECTOS/Cotizadores[]/pdfs/Cotizacion_Nro_1.pdf') as a filename or file
2025-10-17 09:35:13,531 - ERROR - Ocurrió un error inesperado al generar el PDF:
Cannot use PosixPath('/home/krisis/PROYECTOS/Cotizadores[]/pdfs/Cotizacion_Nro_2.pdf') as a filename or file
Traceback (most recent call last):
  File "/home/krisis/PROYECTOS/Cotizadores[]/main.py", line 658, in generar_pdf
    c.save()
    ~~~~~~^^
  File "/home/krisis/PROYECTOS/Copiloto_IA/venv/lib/python3.13/site-packages/reportlab/pdfgen/canvas.py", line 1301, in save
    self._doc.SaveToFile(self._filename, self)
    ~~~~~~~~~~~~~~~~~~~~^^^^^^^^^^^^^^^^^^^^^^
  File "/home/krisis/PROYECTOS/Copiloto_IA/venv/lib/python3.13/site-packages/reportlab/pdfbase/pdfdoc.py", line 210, in SaveToFile
    raise TypeError('Cannot use %s as a filename or file' % repr(filename))
TypeError: Cannot use PosixPath('/home/krisis/PROYECTOS/Cotizadores[]/pdfs/Cotizacion_Nro_2.pdf') as a filename or file
